## 错误处理

Go 语言通过内置的错误接口提供了非常简单的错误处理机制。

error 类型是一个接口类型，这是它的定义：
```go
type error interface {
    Error() string
}
```

我们可以在编码中通过实现 error 接口类型来生成错误信息。
函数通常在最后的返回值中返回错误信息。使用 errors.New 可返回一个错误信息：
```go
func Sqrt(f float64) (float64, error) {
    if f < 0 {
        return 0, errors.New("math: square root of negative number")
    }
    // 实现
}
```

在下面的例子中，我们在调用 Sqrt 的时候传递的一个负数，然后就得到了 non-nil 的 error 对象，将此对象与 nil 比较，结果为 true，所以 fmt.Println(fmt 包在处理 error 时会调用 Error 方法)被调用，以输出错误，请看下面调用的示例代码：

```go
result, err:= Sqrt(-1)

if err != nil {
   fmt.Println(err)
}
```

实例
```go
package main

import (
    "fmt"
)

// 定义一个 DivideError 结构
type DivideError struct {
    dividee int
    divider int
}

// 实现 `error` 接口
func (de *DivideError) Error() string {
    strFormat := `
    Cannot proceed, the divider is zero.
    dividee: %d
    divider: 0
`
    return fmt.Sprintf(strFormat, de.dividee)
}

// 定义 `int` 类型除法运算的函数
func Divide(varDividee int, varDivider int) (result int, errorMsg string) {
    if varDivider == 0 {
            dData := DivideError{
                    dividee: varDividee,
                    divider: varDivider,
            }
            errorMsg = dData.Error()
            return
    } else {
            return varDividee / varDivider, ""
    }

}

func main() {

    // 正常情况
    if result, errorMsg := Divide(100, 10); errorMsg == "" {
            fmt.Println("100/10 = ", result)
    }
    // 当除数为零的时候会返回错误信息
    if _, errorMsg := Divide(100, 0); errorMsg != "" {
            fmt.Println("errorMsg is: ", errorMsg)
    }

}
```

--- 

### 优雅的处理异常

先看一段代码：

```go

package main

import "fmt"

func test() {

	res := 10 / 0
	fmt.Println(res)
}

func main() {

	test()
	fmt.Println("执行下面的代码")
}
```
1. 默认情况下，当发生错误后(Error),程序就会退出(崩溃)
2. 如果我们希望，当发生错误后，可以捕获到错误，并进行处理，保证程序可以继续执行。还可以在捕获到错误后，给管理员发一个消息
3. 这里引入我们将要的错误处理机制

**基本说明**:

1. Go语言追求简洁优雅，所以Go不支持传统的try...catch...finally这个处理
2. Go语言中引入的处理方式为： defer,panic,recover
3. 这几个异常的使用场景可以这么简单描述：Go中可以抛出一个panic的异常，然后在defer中通过recover捕获这个异常，然后正常处理。
```go
package main

import "fmt"

func test() {

	defer func() {
		err := recover()
		if err != nil {
			fmt.Println("错误信息", err)
		}
	}()

	res := 10 / 0
	fmt.Println(res)
}

func main() {

	test()
	fmt.Println("执行下面的代码")
}

```